webapp/public/data/replay_frames.json
{
  "strike_min": 5261.25,
  "strike_max": 5365.5,
  "num_lanes": 24,
  "frames": [
    {
      "frame_index": 0,
      "timestamp": "2025-04-22T15:47:00.237904-04:00",
      "life_progress": 0.0,
      "liquidity_density_factor": 0.092208,
      "gamma_metabolism_factor": 0.218805,
      "manipulation_factor": 0.0,
      "price_kinetic_factor": 0.0,
      "health_score": 0.79819,
      "health_state": "stable",
      "ask_flow": [
        0.0,
        0.0,
        0.0,
        0.0,
        0.0,
        0.0,
        0.0,
        0.0,
        0.0,
        0.0,
        0.0,
        0.065637,
        0.619048,
        0.635779,
        0.487773,
        0.190476,
        0.229086,
        0.16731,
        0.220077,
        0.138996,
        0.938224,
        0.132561,
        0.226512,
        0.05148
      ],
      "bid_flow": [
        0.138996,
        0.129987,
        0.225225,
        0.099099,
        0.199485,
        0.319176,
        0.241956,
        0.163449,
        0.287001,
        0.646075,
        0.546976,
        0.271557,
        0.0,
        0.0,
        0.0,
        0.0,
        0.0,
        0.0,
        0.0,
        0.0,
        0.0,
        0.0,
        0.0,
        0.0
      ],
      "side_imbalance": 0.113128,
      "order_density": 0.125,
      "source_rows": 400,
      "organism_clock": "2025-04-22T15:47:00.237904-04:00"
    },
    {
      "frame_index": 1,
      "timestamp": "2025-04-22T15:47:01.463643-04:00",
      "life_progress": 0.002198,
      "liquidity_density_factor": 0.112987,
      "gamma_metabolism_factor": 0.21997,
      "manipulation_factor": 0.527436,
      "price_kinetic_factor": 0.666667,
      "health_score": 0.483021,
      "health_state": "stressed",
      "ask_flow": [
        0.0,
        0.0,
        0.0,
        0.0,
        0.0,
        0.0,
        0.0,
        0.0,
        0.0,
        0.0,
        0.0,
        0.069498,
        0.606178,
        0.957529,
        0.166023,
        0.190476,
        0.229086,
        0.16731,
        0.220077,
        0.138996,
        0.938224,
        0.132561,
        0.238095,
        0.05148
      ],
      "bid_flow": [
        0.138996,
        0.129987,
        0.225225,
        0.099099,
        0.199485,
        0.319176,
        0.241956,
        0.163449,
        0.287001,
        0.646075,
        0.540541,
        0.29601,
        0.0,
        0.0,
        0.0,
        0.0,
        0.0,
        0.0,
        0.0,
        0.0,
        0.0,
        0.0,
        0.0,
        0.0
      ],
      "side_imbalance": 0.110724,
      "order_density": 0.225,
      "source_rows": 400,
      "organism_clock": "2025-04-22T15:47:00.368852-04:00"
    },
    {
      "frame_index": 2,
      "timestamp": "2025-04-22T15:47:01.482593-04:00",
      "life_progress": 0.004396,
      "liquidity_density_factor": 0.112987,
      "gamma_metabolism_factor": 0.21997,
      "manipulation_factor": 0.527436,
      "price_kinetic_factor": 0.0,
      "health_score": 0.616355,
      "health_state": "stressed",
      "ask_flow": [
        0.0,
        0.0,
        0.0,
        0.0,
        0.0,
        0.0,
        0.0,
        0.0,
        0.0,
        0.0,
        0.0,
        0.069498,
        0.606178,
        0.957529,
        0.166023,
        0.190476,
        0.229086,
        0.16731,
        0.220077,
        0.138996,
        0.938224,
        0.132561,
        0.238095,
        0.05148
      ],
      "bid_flow": [
        0.138996,
        0.129987,
        0.225225,
        0.099099,
        0.199485,
        0.319176,
        0.241956,
        0.163449,
        0.287001,
        0.646075,
        0.540541,
        0.29601,
        0.0,
        0.0,
        0.0,
        0.0,
        0.0,
        0.0,
        0.0,
        0.0,
        0.0,
        0.0,
        0.0,
        0.0
      ],
      "side_imbalance": 0.110724,
      "order_density": 0.225,
      "source_rows": 400,
      "organism_clock": "2025-04-22T15:47:00.499801-04:00"
    },
    {
      "frame_index": 3,
      "timestamp": "2025-04-22T15:47:01.501541-04:00",
      "life_progress": 0.006593,
      "liquidity_density_factor": 0.080519,
      "gamma_metabolism_factor": 0.210188,
      "manipulation_factor": 0.51773,
      "price_kinetic_factor": 0.0,
      "health_score": 0.617816,
      "health_state": "stressed",
      "ask_flow": [
        0.0,
        0.0,
        0.0,
        0.0,
        0.0,
        0.0,
        0.0,
        0.0,
        0.0,
        0.0,
        0.0,
        0.05148,
        0.606178,
        0.957529,
        0.166023,
        0.190476,
        0.229086,
        0.16731,
        0.220077,
        0.138996,
        0.938224,
        0.132561,
        0.238095,
        0.063063
      ],
      "bid_flow": [
        0.138996,
        0.129987,
        0.225225,
        0.099099,
        0.199485,
        0.319176,
        0.241956,
        0.163449,
        0.287001,
        0.646075,
        0.540541,
        0.27027,
        0.0,
        0.0,
        0.0,
        0.0,
        0.0,
        0.0,
        0.0,
        0.0,
        0.0,
        0.0,
        0.0,
        0.0
      ],
      "side_imbalance": 0.113831,
      "order_density": 0.2,
      "source_rows": 400,
      "organism_clock": "2025-04-22T15:47:00.630689-04:00"
    },
    {
      "frame_index": 4,
      "timestamp": "2025-04-22T15:47:01.521996-04:00",
      "life_progress": 0.008791,
      "liquidity_density_factor": 0.107792,
      "gamma_metabolism_factor": 0.21997,
      "manipulation_factor": 0.525943,
      "price_kinetic_factor": 0.0,
      "health_score": 0.616098,
      "health_state": "stressed",
      "ask_flow": [
        0.0,
        0.0,
        0.0,
        0.0,
        0.0,
        0.0,
        0.0,
        0.0,
        0.0,
        0.0,
        0.0,
        0.069498,
        0.606178,
        0.957529,
        0.166023,
        0.190476,
        0.229086,
        0.16731,
        0.220077,
        0.138996,
        0.938224,
        0.132561,
        0.238095,
        0.05148
      ],
      "bid_flow": [
        0.138996,
        0.129987,
        0.225225,
        0.099099,
        0.199485,
        0.319176,
        0.241956,
        0.163449,
        0.287001,
        0.646075,
        0.540541,
        0.290862,
        0.0,
        0.0,
        0.0,
        0.0,
        0.0,
        0.0,
        0.0,
        0.0,
        0.0,
        0.0,
        0.0,
        0.0
      ],
      "side_imbalance": 0.111498,
      "order_density": 0.2,
      "source_rows": 400,
      "organism_clock": "2025-04-22T15:47:00.761638-04:00"
    },
    {
      "frame_index": 5,
      "timestamp": "2025-04-22T15:47:01.541942-04:00",
      "life_progress": 0.010989,
      "liquidity_density_factor": 0.076623,
      "gamma_metabolism_factor": 0.21997,
      "manipulation_factor": 0.528182,
      "price_kinetic_factor": 0.0,
      "health_score": 0.610639,
      "health_state": "stressed",
      "ask_flow": [
        0.0,
        0.0,
        0.0,
        0.0,
        0.0,
        0.0,
        0.0,
        0.0,
        0.0,
        0.0,
        0.0,
        0.07722,
        0.619048,
        0.957529,
        0.166023,
        0.190476,
        0.229086,
        0.16731,
        0.220077,
        0.138996,
        0.938224,
        0.132561,
        0.238095,
        0.05148
      ],
      "bid_flow": [
        0.138996,
        0.129987,
        0.225225,
        0.099099,
        0.199485,
        0.319176,
        0.241956,
        0.163449,
        0.287001,
        0.646075,
        0.545689,
        0.234234,
        0.0,
        0.0,
        0.0,
        0.0,
        0.0,
        0.0,
        0.0,
        0.0,
        0.0,
        0.0,
        0.0,
        0.0
      ],
      "side_imbalance": 0.121763,
      "order_density": 0.125,
      "source_rows": 400,
      "organism_clock": "2025-04-22T15:47:00.892586-04:00"
    },
    {
      "frame_index": 6,
      "timestamp": "2025-04-22T15:47:01.559894-04:00",
      "life_progress": 0.013187,
